ERROR   2022-06-15 18:31:03,951  D:\work_code\pytest-auto-api2\logs\error.log:conftest.py:133 异常用例数: 0
ERROR   2022-06-15 18:31:03,955  D:\work_code\pytest-auto-api2\logs\error.log:conftest.py:134 失败用例数: 0
ERROR   2022-06-16 14:06:20,597  D:\work_code\pytest-auto-api2\logs\error.log:conftest.py:133 异常用例数: 0
ERROR   2022-06-16 14:06:20,597  D:\work_code\pytest-auto-api2\logs\error.log:conftest.py:134 失败用例数: 0
ERROR   2022-06-16 14:52:25,162  D:\work_code\pytest-auto-api2\logs\error.log:requestControl.py:169 缓存写入失败，接口返回数据 <Response [200]> ，jsonpath内容：{'jsonpath': '$.data.[0].[0].id', 'cache_name': 'woshi'}
ERROR   2022-06-16 15:10:03,861  D:\work_code\pytest-auto-api2\logs\error.log:requestControl.py:176 缓存写入失败，接口返回数据 {'cache_type': 'request', 'jsonpath': '$.user_name', 'cache_name': 'woshi'} ，接口请求数据 <MultipartEncoder: {'username': '18800000001', 'password': '123456'}>,jsonpath内容：{'cache_type': 'request', 'jsonpath': '$.user_name', 'cache_name': 'woshi'}
ERROR   2022-06-16 15:10:50,081  D:\work_code\pytest-auto-api2\logs\error.log:requestControl.py:176 缓存写入失败，接口返回数据 {'cache_type': 'request', 'jsonpath': '$.user_name', 'cache_name': 'woshi'} ，接口请求数据 {'username': '18800000001', 'password': '123456'},jsonpath内容：{'cache_type': 'request', 'jsonpath': '$.user_name', 'cache_name': 'woshi'}
ERROR   2022-06-17 10:54:23,848  D:\work_code\pytest-auto-api2\logs\error.log:requestControl.py:176 缓存写入失败，接口返回数据 {'cache_type': 'request', 'jsonpath': '$.random_data', 'cache_name': 'woshi'} ，接口请求数据 {'username': '18800000001', 'password': '123456'},jsonpath内容：{'cache_type': 'request', 'jsonpath': '$.random_data', 'cache_name': 'woshi'}
ERROR   2022-06-17 11:00:17,364  D:\work_code\pytest-auto-api2\logs\error.log:mysqlControl.py:41 数据库连接失败，失败原因(2003, "Can't connect to MySQL server on '47.108.221.85' ([WinError 10061] 由于目标计算机积极拒绝，无法连接。)")
ERROR   2022-06-17 11:00:17,364  D:\work_code\pytest-auto-api2\logs\error.log:mysqlControl.py:87 数据库连接失败，失败原因'MysqlDB' object has no attribute 'cur'
ERROR   2022-06-17 11:00:57,735  D:\work_code\pytest-auto-api2\logs\error.log:mysqlControl.py:40 数据库连接失败，失败原因object supporting the buffer API required
ERROR   2022-06-17 11:00:57,736  D:\work_code\pytest-auto-api2\logs\error.log:mysqlControl.py:86 数据库连接失败，失败原因'MysqlDB' object has no attribute 'cur'
ERROR   2022-06-17 11:06:48,022  D:\work_code\pytest-auto-api2\logs\error.log:conftest.py:133 异常用例数: 0
ERROR   2022-06-17 11:06:48,023  D:\work_code\pytest-auto-api2\logs\error.log:conftest.py:134 失败用例数: 0
ERROR   2022-06-17 11:07:21,006  D:\work_code\pytest-auto-api2\logs\error.log:conftest.py:133 异常用例数: 0
ERROR   2022-06-17 11:07:21,007  D:\work_code\pytest-auto-api2\logs\error.log:conftest.py:134 失败用例数: 0
ERROR   2022-06-17 18:14:23,872  D:\work_code\pytest-auto-api2\logs\error.log:conftest.py:133 异常用例数: 0
ERROR   2022-06-17 18:14:23,872  D:\work_code\pytest-auto-api2\logs\error.log:conftest.py:134 失败用例数: 1
ERROR   2022-06-17 18:14:52,016  D:\work_code\pytest-auto-api2\logs\error.log:conftest.py:133 异常用例数: 0
ERROR   2022-06-17 18:14:52,017  D:\work_code\pytest-auto-api2\logs\error.log:conftest.py:134 失败用例数: 0
